Workbook

Sheet 2026최종정리(전분원)
A1: 이름 | B1: 분원 | C1: 구분 | D1: 계열 | E1: 최종대 | F1: 최종학과
A2: 류하영 | B2: 강남 | C2: 일반 | D2: 인문 | E2: 경기대 | F2: 응용통계학
A3: 이주찬 | B3: 강남 | C3: 일반 | D3: 인문 | E3: 경기대 | F3: 일어일문학
A4: 이승민 | B4: 강남 | C4: 일반 | D4: 인문 | E4: 경기대 | F4: 프랑스어문학
A5: 김청명 | B5: 강남 | C5: 일반 | D5: 인문 | E5: 국민대 | F5: 산림환경시스템학
A6: 홍은지 | B6: 강남 | C6: 일반 | D6: 인문 | E6: 단국대 | F6: 국어국문학
A7: 김서현 | B7: 강남 | C7: 일반 | D7: 인문 | E7: 단국대 | F7: 체육교육학
A8: 김연수 | B8: 강남 | C8: 일반 | D8: 인문 | E8: 단국대 | F8: 체육교육학
A9: 김정은 | B9: 강남 | C9: 일반 | D9: 인문 | E9: 덕성여대 | F9: 바이오공학
A10: 홍예지 | B10: 강남 | C10: 일반 | D10: 인문 | E10: 삼육대 | F10: 영어영문학
A11: 이예은 | B11: 강남 | C11: 일반 | D11: 인문 | E11: 서울여대 | F11: 아동학
A12: 김지민 | B12: 강남 | C12: 일반 | D12: 인문 | E12: 수원대 | F12: 건축학
... A110: 김평호 | B110: 노원 | C110: 일반 | D110: 자연 | E110: 한국항공대 | F110: 기계항공공학
A111: 임채영 | B111: 노원 | C111: 일반 | D111: 자연 | E111: 합격대학모름
A112: 오종혁 | B112: 노원 | C112: 일반 | D112: 자연 | E112: 홍익대 | F112: 전자전기공학
A113: 최여원 | B113: 노원 | C113: 학사 | D113: 인문 | E113: 단국대 | F113: 정치외교학
A114: 김윤서 | B114: 노원 | C114: 학사 | D114: 인문 | E114: 덕성여대 | F114: 사학
A115: 김지혜 | B115: 노원 | C115: 학사 | D115: 인문 | E115: 덕성여대 | F115: 영어영문학
A116: 박여울 | B116: 노원 | C116: 학사 | D116: 인문 | E116: 명지대 | F116: 경영학
A117: 임동섭 | B117: 노원 | C117: 학사 | D117: 인문 | E117: 명지대 | F117: 디지털미디어학
A118: 조윤서 | B118: 노원 | C118: 학사 | D118: 인문 | E118: 서울대 | F118: 산업인력개발학
A119: 김규린 | B119: 노원 | C119: 학사 | D119: 인문 | E119: 성균관대 | F119: 국어국문학
A120: 한상빈 | B120: 노원 | C120: 학사 | D120: 인문 | E120: 한성대 | F120: 크리에이티브인문학
A121: 박시하 | B121: 노원 | C121: 학사 | D121: 인문 | E121: 홍익대 | F121: 영어영문학
A122: 이동규 | B122: 노원 | C122: 학사 | D122: 자연 | E122: 가천대 | F122: 생명과학
A123: 임서연 | B123: 노원 | C123: 학사 | D123: 자연 | E123: 건국대 | F123: 생물공학
... A271: 하상진 | B271: 일산 | C271: 일반 | D271: 인문 | E271: 서강대 | F271: 경영학
A272: 정영민 | B272: 일산 | C272: 일반 | D272: 인문 | E272: 서울디지털대
A273: 임채영 | B273: 일산 | C273: 일반 | D273: 인문 | E273: 서울여대 | F273: 경제학
A274: 주예나 | B274: 일산 | C274: 일반 | D274: 인문 | E274: 세종대 | F274: 인문사회계열
A275: 정유현 | B275: 일산 | C275: 일반 | D275: 인문 | E275: 인하대 | F275: 국제통상학
A276: 정다현 | B276: 일산 | C276: 일반 | D276: 인문 | E276: 한국공학대 | F276: IT경영
A277: 노예송 | B277: 일산 | C277: 일반 | D277: 인문 | E277: 한성대 | F277: 글로벌패션산업학
A278: 김동욱 | B278: 일산 | C278: 일반 | D278: 인문 | E278: 홍익대 | F278: 경영학
A279: 김상엽 | B279: 일산 | C279: 일반 | D279: 자연 | E279: 가천대 | F279: 금융수학
A280: 임준석 | B280: 일산 | C280: 일반 | D280: 자연 | E280: 가천대 | F280: 신소재공학
A281: 정범권 | B281: 일산 | C281: 일반 | D281: 자연 | E281: 가천대
A282: 조태연 | B282: 일산 | C282: 일반 | D282: 자연 | E282: 건국대 | F282: 산업공학
A283: 박민정 | B283: 일산 | C283: 일반 | D283: 자연 | E283: 건국대 | F283: 첨단바이오공학
A284: 이준호 | B284: 일산 | C284: 일반 | D284: 자연 | E284: 경기대 | F284: 전자공학
...

Sheet 통계
A1: 인원수 | B1: 일반인문 | F1: 일반자연 | J1: 학사인문 | N1: 학사자연 | R1: 인문 | V1: 자연 | Z1: 전체 분원
B2: 총원 | C2: 합격 | D2: 상위권 | E2: 준상위권 | F2: 총원 | G2: 합격 | H2: 상위권 | I2: 준상위권 | J2: 총원 | K2: 합격 | L2: 상위권 | M2: 준상위권 | N2: 총원 | O2: 합격 | P2: 상위권 | Q2: 준상위권 | R2: 총원 | S2: 합격 | T2: 상위권 | U2: 준상위권 | V2: 총원 | W2: 합격 | X2: 상위권 | Y2: 준상위권 | Z2: 총원 | AA2: 합격 | AB2: 상위권 | AC2: 준상위권
A3: 강남 | B3: =COUNTIFS('2026최종정리(전분원)'!B:B,A3,'2026최종정리(전분원)'!C:C,"일반",'2026최종정리(전분원)'!D:D,"인문",'2026최종정리(전분원)'!#REF!,"")+C3 -> #REF! | C3: =COUNTIFS('2026최종정리(전분원)'!B:B,A3,'2026최종정리(전분원)'!C:C,"일반",'2026최종정리(전분원)'!D:D,"인문",'2026최종정리(전분원)'!#REF!,"O") -> #REF! | D3: =COUNTIFS('2026최종정리(전분원)'!B:B,A3,'2026최종정리(전분원)'!C:C,"일반",'2026최종정리(전분원)'!D:D,"인문",'2026최종정리(전분원)'!#REF!,"O",'2026최종정리(전분원)'!#REF!,"O") -> #REF! | E3: =COUNTIFS('2026최종정리(전분원)'!B:B,A3,'2026최종정리(전분원)'!C:C,"일반",'2026최종정리(전분원)'!D:D,"인문",'2026최종정리(전분원)'!#REF!,"O",'2026최종정리(전분원)'!#REF!,"O") -> #REF! | F3: =COUNTIFS('2026최종정리(전분원)'!B:B,A3,'2026최종정리(전분원)'!C:C,"일반",'2026최종정리(전분원)'!D:D,"자연",'2026최종정리(전분원)'!#REF!,"")+G3 -> #REF! | G3: =COUNTIFS('2026최종정리(전분원)'!B:B,A3,'2026최종정리(전분원)'!C:C,"일반",'2026최종정리(전분원)'!D:D,"자연",'2026최종정리(전분원)'!#REF!,"O") -> #REF! | H3: =COUNTIFS('2026최종정리(전분원)'!B:B,A3,'2026최종정리(전분원)'!C:C,"일반",'2026최종정리(전분원)'!D:D,"자연",'2026최종정리(전분원)'!#REF!,"O",'2026최종정리(전분원)'!#REF!,"O") -> #REF! | I3: =COUNTIFS('2026최종정리(전분원)'!B:B,A3,'2026최종정리(전분원)'!C:C,"일반",'2026최종정리(전분원)'!D:D,"자연",'2026최종정리(전분원)'!#REF!,"O",'2026최종정리(전분원)'!#REF!,"O") -> #REF! | J3: =COUNTIFS('2026최종정리(전분원)'!B:B,A3,'2026최종정리(전분원)'!C:C,"학사",'2026최종정리(전분원)'!D:D,"인문",'2026최종정리(전분원)'!#REF!,"")+K3 -> #REF! | K3: =COUNTIFS('2026최종정리(전분원)'!B:B,A3,'2026최종정리(전분원)'!C:C,"학사",'2026최종정리(전분원)'!D:D,"인문",'2026최종정리(전분원)'!#REF!,"O") -> #REF! | L3: =COUNTIFS('2026최종정리(전분원)'!B:B,A3,'2026최종정리(전분원)'!C:C,"학사",'2026최종정리(전분원)'!D:D,"인문",'2026최종정리(전분원)'!#REF!,"O",'2026최종정리(전분원)'!#REF!,"O") -> #REF! | M3: =COUNTIFS('2026최종정리(전분원)'!B:B,A3,'2026최종정리(전분원)'!C:C,"학사",'2026최종정리(전분원)'!D:D,"인문",'2026최종정리(전분원)'!#REF!,"O",'2026최종정리(전분원)'!#REF!,"O") -> #REF! | N3: =COUNTIFS('2026최종정리(전분원)'!B:B,A3,'2026최종정리(전분원)'!C:C,"학사",'2026최종정리(전분원)'!D:D,"자연",'2026최종정리(전분원)'!#REF!,"")+O3 -> #REF! | O3: =COUNTIFS('2026최종정리(전분원)'!B:B,A3,'2026최종정리(전분원)'!C:C,"학사",'2026최종정리(전분원)'!D:D,"자연",'2026최종정리(전분원)'!#REF!,"O") -> #REF! | P3: =COUNTIFS('2026최종정리(전분원)'!B:B,A3,'2026최종정리(전분원)'!C:C,"학사",'2026최종정리(전분원)'!D:D,"자연",'2026최종정리(전분원)'!#REF!,"O",'2026최종정리(전분원)'!#REF!,"O") -> #REF! | Q3: =COUNTIFS('2026최종정리(전분원)'!B:B,A3,'2026최종정리(전분원)'!C:C,"학사",'2026최종정리(전분원)'!D:D,"자연",'2026최종정리(전분원)'!#REF!,"O",'2026최종정리(전분원)'!#REF!,"O") -> #REF! | R3: =B3+J3 -> #REF! | S3: =C3+K3 -> #REF! | T3: =D3+L3 -> #REF! | U3: =E3+M3 -> #REF! | V3: =F3+N3 -> #REF! | W3: =G3+O3 -> #REF! | X3: =H3+P3 -> #REF! | Y3: =I3+Q3 -> #REF! | Z3: =R3+V3 -> #REF! | AA3: =S3+W3 -> #REF! | AB3: =T3+X3 -> #REF! | AC3: =U3+Y3 -> #REF!
A4: 노원 | B4: =COUNTIFS('2026최종정리(전분원)'!B:B,A4,'2026최종정리(전분원)'!C:C,"일반",'2026최종정리(전분원)'!D:D,"인문",'2026최종정리(전분원)'!#REF!,"")+C4 -> #REF! | C4: =COUNTIFS('2026최종정리(전분원)'!B:B,A4,'2026최종정리(전분원)'!C:C,"일반",'2026최종정리(전분원)'!D:D,"인문",'2026최종정리(전분원)'!#REF!,"O") -> #REF! | D4: =COUNTIFS('2026최종정리(전분원)'!B:B,A4,'2026최종정리(전분원)'!C:C,"일반",'2026최종정리(전분원)'!D:D,"인문",'2026최종정리(전분원)'!#REF!,"O",'2026최종정리(전분원)'!#REF!,"O") -> #REF! | E4: =COUNTIFS('2026최종정리(전분원)'!B:B,A4,'2026최종정리(전분원)'!C:C,"일반",'2026최종정리(전분원)'!D:D,"인문",'2026최종정리(전분원)'!#REF!,"O",'2026최종정리(전분원)'!#REF!,"O") -> #REF! | F4: =COUNTIFS('2026최종정리(전분원)'!B:B,A4,'2026최종정리(전분원)'!C:C,"일반",'2026최종정리(전분원)'!D:D,"자연",'2026최종정리(전분원)'!#REF!,"")+G4 -> #REF! | G4: =COUNTIFS('2026최종정리(전분원)'!B:B,A4,'2026최종정리(전분원)'!C:C,"일반",'2026최종정리(전분원)'!D:D,"자연",'2026최종정리(전분원)'!#REF!,"O") -> #REF! | H4: =COUNTIFS('2026최종정리(전분원)'!B:B,A4,'2026최종정리(전분원)'!C:C,"일반",'2026최종정리(전분원)'!D:D,"자연",'2026최종정리(전분원)'!#REF!,"O",'2026최종정리(전분원)'!#REF!,"O") -> #REF! | I4: =COUNTIFS('2026최종정리(전분원)'!B:B,A4,'2026최종정리(전분원)'!C:C,"일반",'2026최종정리(전분원)'!D:D,"자연",'2026최종정리(전분원)'!#REF!,"O",'2026최종정리(전분원)'!#REF!,"O") -> #REF! | J4: =COUNTIFS('2026최종정리(전분원)'!B:B,A4,'2026최종정리(전분원)'!C:C,"학사",'2026최종정리(전분원)'!D:D,"인문",'2026최종정리(전분원)'!#REF!,"")+K4 -> #REF! | K4: =COUNTIFS('2026최종정리(전분원)'!B:B,A4,'2026최종정리(전분원)'!C:C,"학사",'2026최종정리(전분원)'!D:D,"인문",'2026최종정리(전분원)'!#REF!,"O") -> #REF! | L4: =COUNTIFS('2026최종정리(전분원)'!B:B,A4,'2026최종정리(전분원)'!C:C,"학사",'2026최종정리(전분원)'!D:D,"인문",'2026최종정리(전분원)'!#REF!,"O",'2026최종정리(전분원)'!#REF!,"O") -> #REF! | M4: =COUNTIFS('2026최종정리(전분원)'!B:B,A4,'2026최종정리(전분원)'!C:C,"학사",'2026최종정리(전분원)'!D:D,"인문",'2026최종정리(전분원)'!#REF!,"O",'2026최종정리(전분원)'!#REF!,"O") -> #REF! | N4: =COUNTIFS('2026최종정리(전분원)'!B:B,A4,'2026최종정리(전분원)'!C:C,"학사",'2026최종정리(전분원)'!D:D,"자연",'2026최종정리(전분원)'!#REF!,"")+O4 -> #REF! | O4: =COUNTIFS('2026최종정리(전분원)'!B:B,A4,'2026최종정리(전분원)'!C:C,"학사",'2026최종정리(전분원)'!D:D,"자연",'2026최종정리(전분원)'!#REF!,"O") -> #REF! | P4: =COUNTIFS('2026최종정리(전분원)'!B:B,A4,'2026최종정리(전분원)'!C:C,"학사",'2026최종정리(전분원)'!D:D,"자연",'2026최종정리(전분원)'!#REF!,"O",'2026최종정리(전분원)'!#REF!,"O") -> #REF! | Q4: =COUNTIFS('2026최종정리(전분원)'!B:B,A4,'2026최종정리(전분원)'!C:C,"학사",'2026최종정리(전분원)'!D:D,"자연",'2026최종정리(전분원)'!#REF!,"O",'2026최종정리(전분원)'!#REF!,"O") -> #REF! | R4: =B4+J4 -> #REF! | S4: =C4+K4 -> #REF! | T4: =D4+L4 -> #REF! | U4: =E4+M4 -> #REF! | V4: =F4+N4 -> #REF! | W4: =G4+O4 -> #REF! | X4: =H4+P4 -> #REF! | Y4: =I4+Q4 -> #REF! | Z4: =R4+V4 -> #REF! | AA4: =S4+W4 -> #REF! | AB4: =T4+X4 -> #REF! | AC4: =U4+Y4 -> #REF!
A5: 일산 | B5: =COUNTIFS('2026최종정리(전분원)'!B:B,A5,'2026최종정리(전분원)'!C:C,"일반",'2026최종정리(전분원)'!D:D,"인문",'2026최종정리(전분원)'!#REF!,"")+C5 -> #REF! | C5: =COUNTIFS('2026최종정리(전분원)'!B:B,A5,'2026최종정리(전분원)'!C:C,"일반",'2026최종정리(전분원)'!D:D,"인문",'2026최종정리(전분원)'!#REF!,"O") -> #REF! | D5: =COUNTIFS('2026최종정리(전분원)'!B:B,A5,'2026최종정리(전분원)'!C:C,"일반",'2026최종정리(전분원)'!D:D,"인문",'2026최종정리(전분원)'!#REF!,"O",'2026최종정리(전분원)'!#REF!,"O") -> #REF! | E5: =COUNTIFS('2026최종정리(전분원)'!B:B,A5,'2026최종정리(전분원)'!C:C,"일반",'2026최종정리(전분원)'!D:D,"인문",'2026최종정리(전분원)'!#REF!,"O",'2026최종정리(전분원)'!#REF!,"O") -> #REF! | F5: =COUNTIFS('2026최종정리(전분원)'!B:B,A5,'2026최종정리(전분원)'!C:C,"일반",'2026최종정리(전분원)'!D:D,"자연",'2026최종정리(전분원)'!#REF!,"")+G5 -> #REF! | G5: =COUNTIFS('2026최종정리(전분원)'!B:B,A5,'2026최종정리(전분원)'!C:C,"일반",'2026최종정리(전분원)'!D:D,"자연",'2026최종정리(전분원)'!#REF!,"O") -> #REF! | H5: =COUNTIFS('2026최종정리(전분원)'!B:B,A5,'2026최종정리(전분원)'!C:C,"일반",'2026최종정리(전분원)'!D:D,"자연",'2026최종정리(전분원)'!#REF!,"O",'2026최종정리(전분원)'!#REF!,"O") -> #REF! | I5: =COUNTIFS('2026최종정리(전분원)'!B:B,A5,'2026최종정리(전분원)'!C:C,"일반",'2026최종정리(전분원)'!D:D,"자연",'2026최종정리(전분원)'!#REF!,"O",'2026최종정리(전분원)'!#REF!,"O") -> #REF! | J5: =COUNTIFS('2026최종정리(전분원)'!B:B,A5,'2026최종정리(전분원)'!C:C,"학사",'2026최종정리(전분원)'!D:D,"인문",'2026최종정리(전분원)'!#REF!,"")+K5 -> #REF! | K5: =COUNTIFS('2026최종정리(전분원)'!B:B,A5,'2026최종정리(전분원)'!C:C,"학사",'2026최종정리(전분원)'!D:D,"인문",'2026최종정리(전분원)'!#REF!,"O") -> #REF! | L5: =COUNTIFS('2026최종정리(전분원)'!B:B,A5,'2026최종정리(전분원)'!C:C,"학사",'2026최종정리(전분원)'!D:D,"인문",'2026최종정리(전분원)'!#REF!,"O",'2026최종정리(전분원)'!#REF!,"O") -> #REF! | M5: =COUNTIFS('2026최종정리(전분원)'!B:B,A5,'2026최종정리(전분원)'!C:C,"학사",'2026최종정리(전분원)'!D:D,"인문",'2026최종정리(전분원)'!#REF!,"O",'2026최종정리(전분원)'!#REF!,"O") -> #REF! | N5: =COUNTIFS('2026최종정리(전분원)'!B:B,A5,'2026최종정리(전분원)'!C:C,"학사",'2026최종정리(전분원)'!D:D,"자연",'2026최종정리(전분원)'!#REF!,"")+O5 -> #REF! | O5: =COUNTIFS('2026최종정리(전분원)'!B:B,A5,'2026최종정리(전분원)'!C:C,"학사",'2026최종정리(전분원)'!D:D,"자연",'2026최종정리(전분원)'!#REF!,"O") -> #REF! | P5: =COUNTIFS('2026최종정리(전분원)'!B:B,A5,'2026최종정리(전분원)'!C:C,"학사",'2026최종정리(전분원)'!D:D,"자연",'2026최종정리(전분원)'!#REF!,"O",'2026최종정리(전분원)'!#REF!,"O") -> #REF! | Q5: =COUNTIFS('2026최종정리(전분원)'!B:B,A5,'2026최종정리(전분원)'!C:C,"학사",'2026최종정리(전분원)'!D:D,"자연",'2026최종정리(전분원)'!#REF!,"O",'2026최종정리(전분원)'!#REF!,"O") -> #REF! | R5: =B5+J5 -> #REF! | S5: =C5+K5 -> #REF! | T5: =D5+L5 -> #REF! | U5: =E5+M5 -> #REF! | V5: =F5+N5 -> #REF! | W5: =G5+O5 -> #REF! | X5: =H5+P5 -> #REF! | Y5: =I5+Q5 -> #REF! | Z5: =R5+V5 -> #REF! | AA5: =S5+W5 -> #REF! | AB5: =T5+X5 -> #REF! | AC5: =U5+Y5 -> #REF!
A6: 부평 | B6: =COUNTIFS('2026최종정리(전분원)'!B:B,A6,'2026최종정리(전분원)'!C:C,"일반",'2026최종정리(전분원)'!D:D,"인문",'2026최종정리(전분원)'!#REF!,"")+C6 -> #REF! | C6: =COUNTIFS('2026최종정리(전분원)'!B:B,A6,'2026최종정리(전분원)'!C:C,"일반",'2026최종정리(전분원)'!D:D,"인문",'2026최종정리(전분원)'!#REF!,"O") -> #REF! | D6: =COUNTIFS('2026최종정리(전분원)'!B:B,A6,'2026최종정리(전분원)'!C:C,"일반",'2026최종정리(전분원)'!D:D,"인문",'2026최종정리(전분원)'!#REF!,"O",'2026최종정리(전분원)'!#REF!,"O") -> #REF! | E6: =COUNTIFS('2026최종정리(전분원)'!B:B,A6,'2026최종정리(전분원)'!C:C,"일반",'2026최종정리(전분원)'!D:D,"인문",'2026최종정리(전분원)'!#REF!,"O",'2026최종정리(전분원)'!#REF!,"O") -> #REF! | F6: =COUNTIFS('2026최종정리(전분원)'!B:B,A6,'2026최종정리(전분원)'!C:C,"일반",'2026최종정리(전분원)'!D:D,"자연",'2026최종정리(전분원)'!#REF!,"")+G6 -> #REF! | G6: =COUNTIFS('2026최종정리(전분원)'!B:B,A6,'2026최종정리(전분원)'!C:C,"일반",'2026최종정리(전분원)'!D:D,"자연",'2026최종정리(전분원)'!#REF!,"O") -> #REF! | H6: =COUNTIFS('2026최종정리(전분원)'!B:B,A6,'2026최종정리(전분원)'!C:C,"일반",'2026최종정리(전분원)'!D:D,"자연",'2026최종정리(전분원)'!#REF!,"O",'2026최종정리(전분원)'!#REF!,"O") -> #REF! | I6: =COUNTIFS('2026최종정리(전분원)'!B:B,A6,'2026최종정리(전분원)'!C:C,"일반",'2026최종정리(전분원)'!D:D,"자연",'2026최종정리(전분원)'!#REF!,"O",'2026최종정리(전분원)'!#REF!,"O") -> #REF! | J6: =COUNTIFS('2026최종정리(전분원)'!B:B,A6,'2026최종정리(전분원)'!C:C,"학사",'2026최종정리(전분원)'!D:D,"인문",'2026최종정리(전분원)'!#REF!,"")+K6 -> #REF! | K6: =COUNTIFS('2026최종정리(전분원)'!B:B,A6,'2026최종정리(전분원)'!C:C,"학사",'2026최종정리(전분원)'!D:D,"인문",'2026최종정리(전분원)'!#REF!,"O") -> #REF! | L6: =COUNTIFS('2026최종정리(전분원)'!B:B,A6,'2026최종정리(전분원)'!C:C,"학사",'2026최종정리(전분원)'!D:D,"인문",'2026최종정리(전분원)'!#REF!,"O",'2026최종정리(전분원)'!#REF!,"O") -> #REF! | M6: =COUNTIFS('2026최종정리(전분원)'!B:B,A6,'2026최종정리(전분원)'!C:C,"학사",'2026최종정리(전분원)'!D:D,"인문",'2026최종정리(전분원)'!#REF!,"O",'2026최종정리(전분원)'!#REF!,"O") -> #REF! | N6: =COUNTIFS('2026최종정리(전분원)'!B:B,A6,'2026최종정리(전분원)'!C:C,"학사",'2026최종정리(전분원)'!D:D,"자연",'2026최종정리(전분원)'!#REF!,"")+O6 -> #REF! | O6: =COUNTIFS('2026최종정리(전분원)'!B:B,A6,'2026최종정리(전분원)'!C:C,"학사",'2026최종정리(전분원)'!D:D,"자연",'2026최종정리(전분원)'!#REF!,"O") -> #REF! | P6: =COUNTIFS('2026최종정리(전분원)'!B:B,A6,'2026최종정리(전분원)'!C:C,"학사",'2026최종정리(전분원)'!D:D,"자연",'2026최종정리(전분원)'!#REF!,"O",'2026최종정리(전분원)'!#REF!,"O") -> #REF! | Q6: =COUNTIFS('2026최종정리(전분원)'!B:B,A6,'2026최종정리(전분원)'!C:C,"학사",'2026최종정리(전분원)'!D:D,"자연",'2026최종정리(전분원)'!#REF!,"O",'2026최종정리(전분원)'!#REF!,"O") -> #REF! | R6: =B6+J6 -> #REF! | S6: =C6+K6 -> #REF! | T6: =D6+L6 -> #REF! | U6: =E6+M6 -> #REF! | V6: =F6+N6 -> #REF! | W6: =G6+O6 -> #REF! | X6: =H6+P6 -> #REF! | Y6: =I6+Q6 -> #REF! | Z6: =R6+V6 -> #REF! | AA6: =S6+W6 -> #REF! | AB6: =T6+X6 -> #REF! | AC6: =U6+Y6 -> #REF!
A7: 듀이카 | B7: =COUNTIFS('2026최종정리(전분원)'!B:B,A7,'2026최종정리(전분원)'!C:C,"일반",'2026최종정리(전분원)'!D:D,"인문",'2026최종정리(전분원)'!#REF!,"")+C7 -> #REF! | C7: =COUNTIFS('2026최종정리(전분원)'!B:B,A7,'2026최종정리(전분원)'!C:C,"일반",'2026최종정리(전분원)'!D:D,"인문",'2026최종정리(전분원)'!#REF!,"O") -> #REF! | D7: =COUNTIFS('2026최종정리(전분원)'!B:B,A7,'2026최종정리(전분원)'!C:C,"일반",'2026최종정리(전분원)'!D:D,"인문",'2026최종정리(전분원)'!#REF!,"O",'2026최종정리(전분원)'!#REF!,"O") -> #REF! | E7: =COUNTIFS('2026최종정리(전분원)'!B:B,A7,'2026최종정리(전분원)'!C:C,"일반",'2026최종정리(전분원)'!D:D,"인문",'2026최종정리(전분원)'!#REF!,"O",'2026최종정리(전분원)'!#REF!,"O") -> #REF! | F7: =COUNTIFS('2026최종정리(전분원)'!B:B,A7,'2026최종정리(전분원)'!C:C,"일반",'2026최종정리(전분원)'!D:D,"자연",'2026최종정리(전분원)'!#REF!,"")+G7 -> #REF! | G7: =COUNTIFS('2026최종정리(전분원)'!B:B,A7,'2026최종정리(전분원)'!C:C,"일반",'2026최종정리(전분원)'!D:D,"자연",'2026최종정리(전분원)'!#REF!,"O") -> #REF! | H7: =COUNTIFS('2026최종정리(전분원)'!B:B,A7,'2026최종정리(전분원)'!C:C,"일반",'2026최종정리(전분원)'!D:D,"자연",'2026최종정리(전분원)'!#REF!,"O",'2026최종정리(전분원)'!#REF!,"O") -> #REF! | I7: =COUNTIFS('2026최종정리(전분원)'!B:B,A7,'2026최종정리(전분원)'!C:C,"일반",'2026최종정리(전분원)'!D:D,"자연",'2026최종정리(전분원)'!#REF!,"O",'2026최종정리(전분원)'!#REF!,"O") -> #REF! | J7: =COUNTIFS('2026최종정리(전분원)'!B:B,A7,'2026최종정리(전분원)'!C:C,"학사",'2026최종정리(전분원)'!D:D,"인문",'2026최종정리(전분원)'!#REF!,"")+K7 -> #REF! | K7: =COUNTIFS('2026최종정리(전분원)'!B:B,A7,'2026최종정리(전분원)'!C:C,"학사",'2026최종정리(전분원)'!D:D,"인문",'2026최종정리(전분원)'!#REF!,"O") -> #REF! | L7: =COUNTIFS('2026최종정리(전분원)'!B:B,A7,'2026최종정리(전분원)'!C:C,"학사",'2026최종정리(전분원)'!D:D,"인문",'2026최종정리(전분원)'!#REF!,"O",'2026최종정리(전분원)'!#REF!,"O") -> #REF! | M7: =COUNTIFS('2026최종정리(전분원)'!B:B,A7,'2026최종정리(전분원)'!C:C,"학사",'2026최종정리(전분원)'!D:D,"인문",'2026최종정리(전분원)'!#REF!,"O",'2026최종정리(전분원)'!#REF!,"O") -> #REF! | N7: =COUNTIFS('2026최종정리(전분원)'!B:B,A7,'2026최종정리(전분원)'!C:C,"학사",'2026최종정리(전분원)'!D:D,"자연",'2026최종정리(전분원)'!#REF!,"")+O7 -> #REF! | O7: =COUNTIFS('2026최종정리(전분원)'!B:B,A7,'2026최종정리(전분원)'!C:C,"학사",'2026최종정리(전분원)'!D:D,"자연",'2026최종정리(전분원)'!#REF!,"O") -> #REF! | P7: =COUNTIFS('2026최종정리(전분원)'!B:B,A7,'2026최종정리(전분원)'!C:C,"학사",'2026최종정리(전분원)'!D:D,"자연",'2026최종정리(전분원)'!#REF!,"O",'2026최종정리(전분원)'!#REF!,"O") -> #REF! | Q7: =COUNTIFS('2026최종정리(전분원)'!B:B,A7,'2026최종정리(전분원)'!C:C,"학사",'2026최종정리(전분원)'!D:D,"자연",'2026최종정리(전분원)'!#REF!,"O",'2026최종정리(전분원)'!#REF!,"O") -> #REF! | R7: =B7+J7 -> #REF! | S7: =C7+K7 -> #REF! | T7: =D7+L7 -> #REF! | U7: =E7+M7 -> #REF! | V7: =F7+N7 -> #REF! | W7: =G7+O7 -> #REF! | X7: =H7+P7 -> #REF! | Y7: =I7+Q7 -> #REF! | Z7: =R7+V7 -> #REF! | AA7: =S7+W7 -> #REF! | AB7: =T7+X7 -> #REF! | AC7: =U7+Y7 -> #REF!
A8: 듀이카제외 총 | B8: =B3+B4+B5+B6 -> #REF! | C8: =C3+C4+C5+C6 -> #REF! | D8: =D3+D4+D5+D6 -> #REF! | E8: =E3+E4+E5+E6 -> #REF! | F8: =F3+F4+F5+F6 -> #REF! | G8: =G3+G4+G5+G6 -> #REF! | H8: =H3+H4+H5+H6 -> #REF! | I8: =I3+I4+I5+I6 -> #REF! | ... AC8: =AC3+AC4+AC5+AC6 -> #REF!
A9: 총합계 | B9: =SUM(B3:B7) -> #REF! | C9: =SUM(C3:C7) -> #REF! | D9: =SUM(D3:D7) -> #REF! | E9: =SUM(E3:E7) -> #REF! | F9: =SUM(F3:F7) -> #REF! | G9: =SUM(G3:G7) -> #REF! | H9: =SUM(H3:H7) -> #REF! | I9: =SUM(I3:I7) -> #REF! | ... AC9: =SUM(AC3:AC7) -> #REF!
A11: 합격률 | B11: 일반인문 | E11: 일반자연 | H11: 학사인문 | K11: 학사자연 | N11: 인문 | Q11: 자연 | T11: 전체 분원
B12: 합격 | C12: 합격생대비비율 | E12: 합격 | F12: 합격생대비비율 | H12: 합격 | I12: 합격생대비비율 | K12: 합격 | L12: 합격생대비비율 | N12: 합격 | O12: 합격생대비비율 | Q12: 합격 | R12: 합격생대비비율 | T12: 합격 | U12: 합격생대비비율
C13: 상위권 | D13: 준상위권 | F13: 상위권 | G13: 준상위권 | I13: 상위권 | J13: 준상위권 | L13: 상위권 | M13: 준상위권 | O13: 상위권 | P13: 준상위권 | R13: 상위권 | S13: 준상위권 | U13: 상위권 | V13: 준상위권
A14: 강남 | B14: =C3/$B$3 -> #REF! | C14: =D3/C3 -> #REF! | D14: =E3/C3 -> #REF! | E14: =G3/$F$3 -> #REF! | F14: =H3/G3 -> #REF! | G14: =I3/G3 -> #REF! | H14: =K3/$J$3 -> #REF! | I14: =L3/K3 -> #REF! | J14: =M3/K3 -> #REF! | K14: =O3/N3 -> #REF! | L14: =P3/O3 -> #REF! | M14: =Q3/O3 -> #REF! | N14: =S3/R3 -> #REF! | O14: =T3/S3 -> #REF! | P14: =U3/S3 -> #REF! | Q14: =W3/V3 -> #REF! | R14: =X3/W3 -> #REF! | S14: =Y3/W3 -> #REF! | T14: =AA3/Z3 -> #REF! | U14: =AB3/AA3 -> #REF! | V14: =AC3/AA3 -> #REF!
A15: 노원 | B15: =C4/$B$4 -> #REF! | C15: =D4/C4 -> #REF! | D15: =E4/C4 -> #REF! | E15: =G4/$F$4 -> #REF! | F15: =H4/G4 -> #REF! | G15: =I4/G4 -> #REF! | H15: =K4/$J$4 -> #REF! | I15: =L4/K4 -> #REF! | J15: =M4/K4 -> #REF! | K15: =O4/N4 -> #REF! | L15: =P4/O4 -> #REF! | M15: =Q4/O4 -> #REF! | N15: =S4/R4 -> #REF! | O15: =T4/S4 -> #REF! | P15: =U4/S4 -> #REF! | Q15: =W4/V4 -> #REF! | R15: =X4/W4 -> #REF! | S15: =Y4/W4 -> #REF! | T15: =AA4/Z4 -> #REF! | U15: =AB4/AA4 -> #REF! | V15: =AC4/AA4 -> #REF!
A16: 일산 | B16: =C5/$B$5 -> #REF! | C16: =D5/C5 -> #REF! | D16: =E5/C5 -> #REF! | E16: =G5/$F$5 -> #REF! | F16: =H5/G5 -> #REF! | G16: =I5/G5 -> #REF! | H16: =K5/$J$5 -> #REF! | I16: =L5/K5 -> #REF! | J16: =M5/K5 -> #REF! | K16: =O5/N5 -> #REF! | L16: =P5/O5 -> #REF! | M16: =Q5/O5 -> #REF! | N16: =S5/R5 -> #REF! | O16: =T5/S5 -> #REF! | P16: =U5/S5 -> #REF! | Q16: =W5/V5 -> #REF! | R16: =X5/W5 -> #REF! | S16: =Y5/W5 -> #REF! | T16: =AA5/Z5 -> #REF! | U16: =AB5/AA5 -> #REF! | V16: =AC5/AA5 -> #REF!
A17: 부평 | B17: =C6/$B$6 -> #REF! | C17: =D6/C6 -> #REF! | D17: =E6/C6 -> #REF! | E17: =G6/$F$6 -> #REF! | F17: =H6/G6 -> #REF! | G17: =I6/G6 -> #REF! | H17: =K6/$J$6 -> #REF! | I17: =L6/K6 -> #REF! | J17: =M6/K6 -> #REF! | K17: =O6/N6 -> #REF! | L17: =P6/O6 -> #REF! | M17: =Q6/O6 -> #REF! | N17: =S6/R6 -> #REF! | O17: =T6/S6 -> #REF! | P17: =U6/S6 -> #REF! | Q17: =W6/V6 -> #REF! | R17: =X6/W6 -> #REF! | S17: =Y6/W6 -> #REF! | T17: =AA6/Z6 -> #REF! | U17: =AB6/AA6 -> #REF! | V17: =AC6/AA6 -> #REF!
A18: 듀이카 | B18: =C7/$B$7 -> #REF! | C18: =D7/C7 -> #REF! | D18: =E7/C7 -> #REF! | E18: =G7/$F$7 -> #REF! | F18: =H7/G7 -> #REF! | G18: =I7/G7 -> #REF! | H18: =K7/$J$7 -> #REF! | I18: =L7/K7 -> #REF! | J18: =M7/K7 -> #REF! | K18: =O7/N7 -> #REF! | L18: =P7/O7 -> #REF! | M18: =Q7/O7 -> #REF! | N18: =S7/R7 -> #REF! | O18: =T7/S7 -> #REF! | P18: =U7/S7 -> #REF! | Q18: =W7/V7 -> #REF! | R18: =X7/W7 -> #REF! | S18: =Y7/W7 -> #REF! | T18: =AA7/Z7 -> #REF! | U18: =AB7/AA7 -> #REF! | V18: =AC7/AA7 -> #REF!
A19: 듀이카제외 총 | B19: =C8/$B$8 -> #REF! | C19: =D8/C8 -> #REF! | D19: =E8/C8 -> #REF! | E19: =G8/$F$8 -> #REF! | F19: =H8/G8 -> #REF! | G19: =I8/G8 -> #REF! | H19: =K8/$J$8 -> #REF! | I19: =L8/K8 -> #REF! | J19: =M8/K8 -> #REF! | K19: =O8/N8 -> #REF! | L19: =P8/O8 -> #REF! | M19: =Q8/O8 -> #REF! | N19: =S8/R8 -> #REF! | O19: =T8/S8 -> #REF! | P19: =U8/S8 -> #REF! | Q19: =W8/V8 -> #REF! | R19: =X8/W8 -> #REF! | S19: =Y8/W8 -> #REF! | T19: =AA8/Z8 -> #REF! | U19: =AB8/AA8 -> #REF! | V19: =AC8/AA8 -> #REF!
A20: 총합계 | B20: =C9/$B$9 -> #REF! | C20: =D9/C9 -> #REF! | D20: =E9/C9 -> #REF! | E20: =G9/$F$9 -> #REF! | F20: =H9/G9 -> #REF! | G20: =I9/G9 -> #REF! | H20: =K9/$J$9 -> #REF! | I20: =L9/K9 -> #REF! | J20: =M9/K9 -> #REF! | K20: =O9/N9 -> #REF! | L20: =P9/O9 -> #REF! | M20: =Q9/O9 -> #REF! | N20: =S9/R9 -> #REF! | O20: =T9/S9 -> #REF! | P20: =U9/S9 -> #REF! | Q20: =W9/V9 -> #REF! | R20: =X9/W9 -> #REF! | S20: =Y9/W9 -> #REF! | T20: =AA9/Z9 -> #REF! | U20: =AB9/AA9 -> #REF! | V20: =AC9/AA9 -> #REF!
